[2024-03-10 19:23:42,753: INFO: config: PyTorch version 2.2.1 available.]
[2024-03-10 19:23:44,940: INFO: main: >>>>>> stage Data Ingestion stage started <<<<<<]
[2024-03-10 19:23:44,971: INFO: common: yaml file: config\config.yaml loaded successfully]
[2024-03-10 19:23:44,987: INFO: common: yaml file: params.yaml loaded successfully]
[2024-03-10 19:23:45,003: INFO: common: created directory at: artifacts]
[2024-03-10 19:23:45,003: INFO: common: created directory at: artifacts/data_ingestion]
[2024-03-10 19:23:45,003: INFO: data_ingestion: File already exists of size: ~ 7718 KB]
[2024-03-10 19:23:45,737: INFO: main: >>>>>> stage Data Ingestion stage completed <<<<<<

x==========x]
[2024-03-10 19:23:45,737: INFO: main: >>>>>> stage Data Validation stage started <<<<<<]
[2024-03-10 19:23:45,737: INFO: common: yaml file: config\config.yaml loaded successfully]
[2024-03-10 19:23:45,737: INFO: common: yaml file: params.yaml loaded successfully]
[2024-03-10 19:23:45,737: INFO: common: created directory at: artifacts]
[2024-03-10 19:23:45,737: INFO: common: created directory at: artifacts/data_validation]
[2024-03-10 19:23:45,737: INFO: main: >>>>>> stage Data Validation stage completed <<<<<<

x==========x]
[2024-03-10 19:23:45,737: INFO: main: >>>>>> stage Data Transformation stage started <<<<<<]
[2024-03-10 19:23:45,752: INFO: common: yaml file: config\config.yaml loaded successfully]
[2024-03-10 19:23:45,752: INFO: common: yaml file: params.yaml loaded successfully]
[2024-03-10 19:23:45,752: INFO: common: created directory at: artifacts]
[2024-03-10 19:23:45,752: INFO: common: created directory at: artifacts/data_transformation]
[2024-03-10 19:23:59,096: INFO: main: >>>>>> stage Data Transformation stage completed <<<<<<

x==========x]
[2024-03-10 19:23:59,096: INFO: main: *******************]
[2024-03-10 19:23:59,096: INFO: main: >>>>>> stage Model Trainer stage started <<<<<<]
[2024-03-10 19:23:59,096: INFO: common: yaml file: config\config.yaml loaded successfully]
[2024-03-10 19:23:59,096: INFO: common: yaml file: params.yaml loaded successfully]
[2024-03-10 19:23:59,096: INFO: common: created directory at: artifacts]
[2024-03-10 19:23:59,096: INFO: common: created directory at: artifacts/model_trainer]
[2024-03-10 19:56:51,560: WARNING: file_download: Error while downloading from https://cdn-lfs.huggingface.co/google/pegasus-cnn_dailymail/cf34e28157605d3ced3bd184820ea2a9d9a30b69f4bb1df4aaa4145d0850290e?response-content-disposition=attachment%3B+filename*%3DUTF-8%27%27pytorch_model.bin%3B+filename%3D%22pytorch_model.bin%22%3B&response-content-type=application%2Foctet-stream&Expires=1710338043&Policy=eyJTdGF0ZW1lbnQiOlt7IkNvbmRpdGlvbiI6eyJEYXRlTGVzc1RoYW4iOnsiQVdTOkVwb2NoVGltZSI6MTcxMDMzODA0M319LCJSZXNvdXJjZSI6Imh0dHBzOi8vY2RuLWxmcy5odWdnaW5nZmFjZS5jby9nb29nbGUvcGVnYXN1cy1jbm5fZGFpbHltYWlsL2NmMzRlMjgxNTc2MDVkM2NlZDNiZDE4NDgyMGVhMmE5ZDlhMzBiNjlmNGJiMWRmNGFhYTQxNDVkMDg1MDI5MGU%7EcmVzcG9uc2UtY29udGVudC1kaXNwb3NpdGlvbj0qJnJlc3BvbnNlLWNvbnRlbnQtdHlwZT0qIn1dfQ__&Signature=0I-ep3QfPa8fkvLIf4BoF64Ko3fgA49L14n%7ESFVRZXWBvTCgUDYPUw7pFOo3l31f1pu2JkpiZhg5lC-vvk7CtHlYo%7EexRM%7E8yIbCBCHw9w2xU06mkJBYoB59a%7E1EwibNIcvilJqLyUsUgJ7agO2-GuAmUAW3AQcbvoXyXtZLe1Y31zhfYWuJvrptBj4tescpgUfomD2wlo-N2TPdrK6jQ6FfWIZ4cU38xWpFIpRtvMLOhTpeLJA-2k8IT37cwN3EzapnxJXPdJv9TMHsFmNSWBIQ1aiLzd8Cz3ae%7E-494Enq-OaH1b9Swx0yHOZB6j7ZsG3vZDBsnX7RO4B6w5vgTw__&Key-Pair-Id=KVTP0A1DKRTAX: HTTPSConnectionPool(host='cdn-lfs.huggingface.co', port=443): Read timed out.
Trying to resume download...]
[2024-03-10 19:57:08,448: ERROR: main: (MaxRetryError("HTTPSConnectionPool(host='cdn-lfs.huggingface.co', port=443): Max retries exceeded with url: /google/pegasus-cnn_dailymail/cf34e28157605d3ced3bd184820ea2a9d9a30b69f4bb1df4aaa4145d0850290e?response-content-disposition=attachment%3B+filename*%3DUTF-8%27%27pytorch_model.bin%3B+filename%3D%22pytorch_model.bin%22%3B&response-content-type=application%2Foctet-stream&Expires=1710338043&Policy=eyJTdGF0ZW1lbnQiOlt7IkNvbmRpdGlvbiI6eyJEYXRlTGVzc1RoYW4iOnsiQVdTOkVwb2NoVGltZSI6MTcxMDMzODA0M319LCJSZXNvdXJjZSI6Imh0dHBzOi8vY2RuLWxmcy5odWdnaW5nZmFjZS5jby9nb29nbGUvcGVnYXN1cy1jbm5fZGFpbHltYWlsL2NmMzRlMjgxNTc2MDVkM2NlZDNiZDE4NDgyMGVhMmE5ZDlhMzBiNjlmNGJiMWRmNGFhYTQxNDVkMDg1MDI5MGU~cmVzcG9uc2UtY29udGVudC1kaXNwb3NpdGlvbj0qJnJlc3BvbnNlLWNvbnRlbnQtdHlwZT0qIn1dfQ__&Signature=0I-ep3QfPa8fkvLIf4BoF64Ko3fgA49L14n~SFVRZXWBvTCgUDYPUw7pFOo3l31f1pu2JkpiZhg5lC-vvk7CtHlYo~exRM~8yIbCBCHw9w2xU06mkJBYoB59a~1EwibNIcvilJqLyUsUgJ7agO2-GuAmUAW3AQcbvoXyXtZLe1Y31zhfYWuJvrptBj4tescpgUfomD2wlo-N2TPdrK6jQ6FfWIZ4cU38xWpFIpRtvMLOhTpeLJA-2k8IT37cwN3EzapnxJXPdJv9TMHsFmNSWBIQ1aiLzd8Cz3ae~-494Enq-OaH1b9Swx0yHOZB6j7ZsG3vZDBsnX7RO4B6w5vgTw__&Key-Pair-Id=KVTP0A1DKRTAX (Caused by NewConnectionError('<urllib3.connection.HTTPSConnection object at 0x000001D0B6EEFCD0>: Failed to establish a new connection: [WinError 10051] A socket operation was attempted to an unreachable network'))"), '(Request ID: e5f91636-bd11-413b-bada-8361fe88ac00)')]
Traceback (most recent call last):
  File "C:\Users\VIWEK\anaconda3\envs\texts\lib\site-packages\urllib3\response.py", line 444, in _error_catcher
    yield
  File "C:\Users\VIWEK\anaconda3\envs\texts\lib\site-packages\urllib3\response.py", line 567, in read
    data = self._fp_read(amt) if not fp_closed else b""
  File "C:\Users\VIWEK\anaconda3\envs\texts\lib\site-packages\urllib3\response.py", line 533, in _fp_read
    return self._fp.read(amt) if amt is not None else self._fp.read()
  File "C:\Users\VIWEK\anaconda3\envs\texts\lib\http\client.py", line 459, in read
    n = self.readinto(b)
  File "C:\Users\VIWEK\anaconda3\envs\texts\lib\http\client.py", line 503, in readinto
    n = self.fp.readinto(b)
  File "C:\Users\VIWEK\anaconda3\envs\texts\lib\socket.py", line 669, in readinto
    return self._sock.recv_into(b)
  File "C:\Users\VIWEK\anaconda3\envs\texts\lib\ssl.py", line 1274, in recv_into
    return self.read(nbytes, buffer)
  File "C:\Users\VIWEK\anaconda3\envs\texts\lib\ssl.py", line 1132, in read
    return self._sslobj.read(len, buffer)
socket.timeout: The read operation timed out

During handling of the above exception, another exception occurred:

Traceback (most recent call last):
  File "C:\Users\VIWEK\anaconda3\envs\texts\lib\site-packages\requests\models.py", line 816, in generate
    yield from self.raw.stream(chunk_size, decode_content=True)
  File "C:\Users\VIWEK\anaconda3\envs\texts\lib\site-packages\urllib3\response.py", line 628, in stream
    data = self.read(amt=amt, decode_content=decode_content)
  File "C:\Users\VIWEK\anaconda3\envs\texts\lib\site-packages\urllib3\response.py", line 593, in read
    raise IncompleteRead(self._fp_bytes_read, self.length_remaining)
  File "C:\Users\VIWEK\anaconda3\envs\texts\lib\contextlib.py", line 131, in __exit__
    self.gen.throw(type, value, traceback)
  File "C:\Users\VIWEK\anaconda3\envs\texts\lib\site-packages\urllib3\response.py", line 449, in _error_catcher
    raise ReadTimeoutError(self._pool, None, "Read timed out.")
urllib3.exceptions.ReadTimeoutError: HTTPSConnectionPool(host='cdn-lfs.huggingface.co', port=443): Read timed out.

During handling of the above exception, another exception occurred:

Traceback (most recent call last):
  File "C:\Users\VIWEK\anaconda3\envs\texts\lib\site-packages\huggingface_hub\file_download.py", line 547, in http_get
    for chunk in r.iter_content(chunk_size=DOWNLOAD_CHUNK_SIZE):
  File "C:\Users\VIWEK\anaconda3\envs\texts\lib\site-packages\requests\models.py", line 822, in generate
    raise ConnectionError(e)
requests.exceptions.ConnectionError: HTTPSConnectionPool(host='cdn-lfs.huggingface.co', port=443): Read timed out.

During handling of the above exception, another exception occurred:

Traceback (most recent call last):
  File "C:\Users\VIWEK\anaconda3\envs\texts\lib\site-packages\urllib3\connection.py", line 174, in _new_conn
    conn = connection.create_connection(
  File "C:\Users\VIWEK\anaconda3\envs\texts\lib\site-packages\urllib3\util\connection.py", line 95, in create_connection
    raise err
  File "C:\Users\VIWEK\anaconda3\envs\texts\lib\site-packages\urllib3\util\connection.py", line 85, in create_connection
    sock.connect(sa)
OSError: [WinError 10051] A socket operation was attempted to an unreachable network

During handling of the above exception, another exception occurred:

Traceback (most recent call last):
  File "C:\Users\VIWEK\anaconda3\envs\texts\lib\site-packages\urllib3\connectionpool.py", line 715, in urlopen
    httplib_response = self._make_request(
  File "C:\Users\VIWEK\anaconda3\envs\texts\lib\site-packages\urllib3\connectionpool.py", line 404, in _make_request
    self._validate_conn(conn)
  File "C:\Users\VIWEK\anaconda3\envs\texts\lib\site-packages\urllib3\connectionpool.py", line 1058, in _validate_conn
    conn.connect()
  File "C:\Users\VIWEK\anaconda3\envs\texts\lib\site-packages\urllib3\connection.py", line 363, in connect
    self.sock = conn = self._new_conn()
  File "C:\Users\VIWEK\anaconda3\envs\texts\lib\site-packages\urllib3\connection.py", line 186, in _new_conn
    raise NewConnectionError(
urllib3.exceptions.NewConnectionError: <urllib3.connection.HTTPSConnection object at 0x000001D0B6EEFCD0>: Failed to establish a new connection: [WinError 10051] A socket operation was attempted to an unreachable network

During handling of the above exception, another exception occurred:

Traceback (most recent call last):
  File "C:\Users\VIWEK\anaconda3\envs\texts\lib\site-packages\requests\adapters.py", line 486, in send
    resp = conn.urlopen(
  File "C:\Users\VIWEK\anaconda3\envs\texts\lib\site-packages\urllib3\connectionpool.py", line 799, in urlopen
    retries = retries.increment(
  File "C:\Users\VIWEK\anaconda3\envs\texts\lib\site-packages\urllib3\util\retry.py", line 592, in increment
    raise MaxRetryError(_pool, url, error or ResponseError(cause))
urllib3.exceptions.MaxRetryError: HTTPSConnectionPool(host='cdn-lfs.huggingface.co', port=443): Max retries exceeded with url: /google/pegasus-cnn_dailymail/cf34e28157605d3ced3bd184820ea2a9d9a30b69f4bb1df4aaa4145d0850290e?response-content-disposition=attachment%3B+filename*%3DUTF-8%27%27pytorch_model.bin%3B+filename%3D%22pytorch_model.bin%22%3B&response-content-type=application%2Foctet-stream&Expires=1710338043&Policy=eyJTdGF0ZW1lbnQiOlt7IkNvbmRpdGlvbiI6eyJEYXRlTGVzc1RoYW4iOnsiQVdTOkVwb2NoVGltZSI6MTcxMDMzODA0M319LCJSZXNvdXJjZSI6Imh0dHBzOi8vY2RuLWxmcy5odWdnaW5nZmFjZS5jby9nb29nbGUvcGVnYXN1cy1jbm5fZGFpbHltYWlsL2NmMzRlMjgxNTc2MDVkM2NlZDNiZDE4NDgyMGVhMmE5ZDlhMzBiNjlmNGJiMWRmNGFhYTQxNDVkMDg1MDI5MGU~cmVzcG9uc2UtY29udGVudC1kaXNwb3NpdGlvbj0qJnJlc3BvbnNlLWNvbnRlbnQtdHlwZT0qIn1dfQ__&Signature=0I-ep3QfPa8fkvLIf4BoF64Ko3fgA49L14n~SFVRZXWBvTCgUDYPUw7pFOo3l31f1pu2JkpiZhg5lC-vvk7CtHlYo~exRM~8yIbCBCHw9w2xU06mkJBYoB59a~1EwibNIcvilJqLyUsUgJ7agO2-GuAmUAW3AQcbvoXyXtZLe1Y31zhfYWuJvrptBj4tescpgUfomD2wlo-N2TPdrK6jQ6FfWIZ4cU38xWpFIpRtvMLOhTpeLJA-2k8IT37cwN3EzapnxJXPdJv9TMHsFmNSWBIQ1aiLzd8Cz3ae~-494Enq-OaH1b9Swx0yHOZB6j7ZsG3vZDBsnX7RO4B6w5vgTw__&Key-Pair-Id=KVTP0A1DKRTAX (Caused by NewConnectionError('<urllib3.connection.HTTPSConnection object at 0x000001D0B6EEFCD0>: Failed to establish a new connection: [WinError 10051] A socket operation was attempted to an unreachable network'))

During handling of the above exception, another exception occurred:

Traceback (most recent call last):
  File "main.py", line 51, in <module>
    model_trainer.main()
  File "c:\users\viwek\desktop\project\text-summarizer-project\src\textSummarizer\pipeline\stage_04_model_trainer.py", line 14, in main
    model_trainer_config.train()
  File "c:\users\viwek\desktop\project\text-summarizer-project\src\textSummarizer\conponents\model_trainer.py", line 19, in train
    model_pegasus = AutoModelForSeq2SeqLM.from_pretrained(self.config.model_ckpt).to(device)
  File "C:\Users\VIWEK\anaconda3\envs\texts\lib\site-packages\transformers\models\auto\auto_factory.py", line 561, in from_pretrained
    return model_class.from_pretrained(
  File "C:\Users\VIWEK\anaconda3\envs\texts\lib\site-packages\transformers\modeling_utils.py", line 3193, in from_pretrained
    resolved_archive_file = cached_file(
  File "C:\Users\VIWEK\anaconda3\envs\texts\lib\site-packages\transformers\utils\hub.py", line 398, in cached_file
    resolved_file = hf_hub_download(
  File "C:\Users\VIWEK\anaconda3\envs\texts\lib\site-packages\huggingface_hub\utils\_validators.py", line 118, in _inner_fn
    return fn(*args, **kwargs)
  File "C:\Users\VIWEK\anaconda3\envs\texts\lib\site-packages\huggingface_hub\file_download.py", line 1492, in hf_hub_download
    http_get(
  File "C:\Users\VIWEK\anaconda3\envs\texts\lib\site-packages\huggingface_hub\file_download.py", line 564, in http_get
    return http_get(
  File "C:\Users\VIWEK\anaconda3\envs\texts\lib\site-packages\huggingface_hub\file_download.py", line 471, in http_get
    r = _request_wrapper(
  File "C:\Users\VIWEK\anaconda3\envs\texts\lib\site-packages\huggingface_hub\file_download.py", line 408, in _request_wrapper
    response = get_session().request(method=method, url=url, **params)
  File "C:\Users\VIWEK\anaconda3\envs\texts\lib\site-packages\requests\sessions.py", line 589, in request
    resp = self.send(prep, **send_kwargs)
  File "C:\Users\VIWEK\anaconda3\envs\texts\lib\site-packages\requests\sessions.py", line 703, in send
    r = adapter.send(request, **kwargs)
  File "C:\Users\VIWEK\anaconda3\envs\texts\lib\site-packages\huggingface_hub\utils\_http.py", line 67, in send
    return super().send(request, *args, **kwargs)
  File "C:\Users\VIWEK\anaconda3\envs\texts\lib\site-packages\requests\adapters.py", line 519, in send
    raise ConnectionError(e, request=request)
requests.exceptions.ConnectionError: (MaxRetryError("HTTPSConnectionPool(host='cdn-lfs.huggingface.co', port=443): Max retries exceeded with url: /google/pegasus-cnn_dailymail/cf34e28157605d3ced3bd184820ea2a9d9a30b69f4bb1df4aaa4145d0850290e?response-content-disposition=attachment%3B+filename*%3DUTF-8%27%27pytorch_model.bin%3B+filename%3D%22pytorch_model.bin%22%3B&response-content-type=application%2Foctet-stream&Expires=1710338043&Policy=eyJTdGF0ZW1lbnQiOlt7IkNvbmRpdGlvbiI6eyJEYXRlTGVzc1RoYW4iOnsiQVdTOkVwb2NoVGltZSI6MTcxMDMzODA0M319LCJSZXNvdXJjZSI6Imh0dHBzOi8vY2RuLWxmcy5odWdnaW5nZmFjZS5jby9nb29nbGUvcGVnYXN1cy1jbm5fZGFpbHltYWlsL2NmMzRlMjgxNTc2MDVkM2NlZDNiZDE4NDgyMGVhMmE5ZDlhMzBiNjlmNGJiMWRmNGFhYTQxNDVkMDg1MDI5MGU~cmVzcG9uc2UtY29udGVudC1kaXNwb3NpdGlvbj0qJnJlc3BvbnNlLWNvbnRlbnQtdHlwZT0qIn1dfQ__&Signature=0I-ep3QfPa8fkvLIf4BoF64Ko3fgA49L14n~SFVRZXWBvTCgUDYPUw7pFOo3l31f1pu2JkpiZhg5lC-vvk7CtHlYo~exRM~8yIbCBCHw9w2xU06mkJBYoB59a~1EwibNIcvilJqLyUsUgJ7agO2-GuAmUAW3AQcbvoXyXtZLe1Y31zhfYWuJvrptBj4tescpgUfomD2wlo-N2TPdrK6jQ6FfWIZ4cU38xWpFIpRtvMLOhTpeLJA-2k8IT37cwN3EzapnxJXPdJv9TMHsFmNSWBIQ1aiLzd8Cz3ae~-494Enq-OaH1b9Swx0yHOZB6j7ZsG3vZDBsnX7RO4B6w5vgTw__&Key-Pair-Id=KVTP0A1DKRTAX (Caused by NewConnectionError('<urllib3.connection.HTTPSConnection object at 0x000001D0B6EEFCD0>: Failed to establish a new connection: [WinError 10051] A socket operation was attempted to an unreachable network'))"), '(Request ID: e5f91636-bd11-413b-bada-8361fe88ac00)')
